2025-06-24 11:52:21,682 ERROR __main__ Failed to create database tables: (pymysql.err.OperationalError) (2003, "Can't connect to MySQL server on 'localhost' ([WinError 10061] No connection could be made because the target machine actively refused it)")
(Background on this error at: https://sqlalche.me/e/20/e3q8)
2025-06-24 11:52:21,717 INFO werkzeug [31m[1mWARNING: This is a development server. Do not use it in a production deployment. Use a production WSGI server instead.[0m
 * Running on all addresses (0.0.0.0)
 * Running on http://127.0.0.1:5000
 * Running on http://192.168.1.160:5000
2025-06-24 11:52:21,717 INFO werkzeug [33mPress CTRL+C to quit[0m
2025-06-24 12:05:28,709 ERROR __main__ Failed to create database tables: (pymysql.err.OperationalError) (2003, "Can't connect to MySQL server on 'localhost' ([WinError 10061] No connection could be made because the target machine actively refused it)")
(Background on this error at: https://sqlalche.me/e/20/e3q8)
2025-06-24 12:05:28,724 INFO werkzeug [31m[1mWARNING: This is a development server. Do not use it in a production deployment. Use a production WSGI server instead.[0m
 * Running on all addresses (0.0.0.0)
 * Running on http://127.0.0.1:5000
 * Running on http://192.168.1.160:5000
2025-06-24 12:05:28,724 INFO werkzeug [33mPress CTRL+C to quit[0m
2025-06-24 12:07:32,150 ERROR __main__ Failed to create database tables: (pymysql.err.OperationalError) (2003, "Can't connect to MySQL server on 'localhost' ([WinError 10061] No connection could be made because the target machine actively refused it)")
(Background on this error at: https://sqlalche.me/e/20/e3q8)
2025-06-24 12:07:32,171 INFO werkzeug [31m[1mWARNING: This is a development server. Do not use it in a production deployment. Use a production WSGI server instead.[0m
 * Running on all addresses (0.0.0.0)
 * Running on http://127.0.0.1:5000
 * Running on http://192.168.1.160:5000
2025-06-24 12:07:32,171 INFO werkzeug [33mPress CTRL+C to quit[0m
2025-06-24 12:14:20,905 ERROR __main__ Failed to create database tables: (pymysql.err.OperationalError) (2003, "Can't connect to MySQL server on 'localhost' ([WinError 10061] No connection could be made because the target machine actively refused it)")
(Background on this error at: https://sqlalche.me/e/20/e3q8)
2025-06-24 12:14:20,919 INFO werkzeug [31m[1mWARNING: This is a development server. Do not use it in a production deployment. Use a production WSGI server instead.[0m
 * Running on all addresses (0.0.0.0)
 * Running on http://127.0.0.1:5000
 * Running on http://192.168.1.160:5000
2025-06-24 12:14:20,919 INFO werkzeug [33mPress CTRL+C to quit[0m
2025-06-24 14:36:54,650 ERROR __main__ Failed to create database tables: (pymysql.err.OperationalError) (1049, "Unknown database 'singora_db'")
(Background on this error at: https://sqlalche.me/e/20/e3q8)
2025-06-24 14:36:54,666 INFO werkzeug [31m[1mWARNING: This is a development server. Do not use it in a production deployment. Use a production WSGI server instead.[0m
 * Running on all addresses (0.0.0.0)
 * Running on http://127.0.0.1:5000
 * Running on http://192.168.1.160:5000
2025-06-24 14:36:54,667 INFO werkzeug [33mPress CTRL+C to quit[0m
2025-06-24 14:38:24,819 INFO __main__ Database tables created successfully
2025-06-24 14:38:24,834 INFO werkzeug [31m[1mWARNING: This is a development server. Do not use it in a production deployment. Use a production WSGI server instead.[0m
 * Running on all addresses (0.0.0.0)
 * Running on http://127.0.0.1:5000
 * Running on http://192.168.1.160:5000
2025-06-24 14:38:24,834 INFO werkzeug [33mPress CTRL+C to quit[0m
2025-06-24 14:43:49,656 INFO werkzeug 127.0.0.1 - - [24/Jun/2025 14:43:49] "GET /health HTTP/1.1" 200 -
2025-06-24 14:48:56,141 ERROR __main__ Database error: (pymysql.err.DataError) (1406, "Data too long for column 'image' at row 1")
[SQL: INSERT INTO singora_images (image, label_name, date, timestamp) VALUES (%(image)s, %(label_name)s, %(date)s, %(timestamp)s)]
[parameters: {'image': b'\xff\xd8\xff\xe0\x00\x10JFIF\x00\x01\x01\x01\x00`\x00`\x00\x00\xff\xdb\x00C\x00\x04\x03\x03\x04\x03\x03\x04\x04\x03\x04\x05\x04\x04\x05\x06\n\x07\x0 ... (291091 characters truncated) ... 1f\xf4\xf83\xf53\x9b;\xf6\xd8\xff\x00\xb7\xc3?Y\xc3\xf5\x7f\xbc\xfd\x16?\xf3y\xcf\xf8}\x7f\x01\xff\x00_\xa6p\x7f\xc6\x99\xcd\xf8\xc7\x97\xe7?\xff\xd9', 'label_name': 'Naps_slubs', 'date': datetime.date(2025, 6, 24), 'timestamp': datetime.datetime(2025, 6, 24, 9, 18, 56, 134808)}]
(Background on this error at: https://sqlalche.me/e/20/9h9h)
2025-06-24 14:48:56,143 INFO werkzeug 127.0.0.1 - - [24/Jun/2025 14:48:56] "[35m[1mPOST /api/v1/images HTTP/1.1[0m" 500 -
2025-06-24 14:49:34,214 ERROR __main__ Database error: (pymysql.err.DataError) (1406, "Data too long for column 'image' at row 1")
[SQL: INSERT INTO singora_images (image, label_name, date, timestamp) VALUES (%(image)s, %(label_name)s, %(date)s, %(timestamp)s)]
[parameters: {'image': b'\xff\xd8\xff\xe0\x00\x10JFIF\x00\x01\x01\x01\x00`\x00`\x00\x00\xff\xdb\x00C\x00\x04\x03\x03\x04\x03\x03\x04\x04\x03\x04\x05\x04\x04\x05\x06\n\x07\x0 ... (291091 characters truncated) ... 1f\xf4\xf83\xf53\x9b;\xf6\xd8\xff\x00\xb7\xc3?Y\xc3\xf5\x7f\xbc\xfd\x16?\xf3y\xcf\xf8}\x7f\x01\xff\x00_\xa6p\x7f\xc6\x99\xcd\xf8\xc7\x97\xe7?\xff\xd9', 'label_name': 'Naps', 'date': datetime.date(2025, 6, 24), 'timestamp': datetime.datetime(2025, 6, 24, 9, 19, 34, 205446)}]
(Background on this error at: https://sqlalche.me/e/20/9h9h)
2025-06-24 14:49:34,214 INFO werkzeug 127.0.0.1 - - [24/Jun/2025 14:49:34] "[35m[1mPOST /api/v1/images HTTP/1.1[0m" 500 -
2025-06-24 14:53:28,938 INFO __main__ Image uploaded successfully with ID: 1
2025-06-24 14:53:28,939 INFO werkzeug 127.0.0.1 - - [24/Jun/2025 14:53:28] "[35m[1mPOST /api/v1/images HTTP/1.1[0m" 201 -
2025-06-24 14:54:10,595 INFO __main__ Image uploaded successfully with ID: 2
2025-06-24 14:54:10,596 INFO werkzeug 127.0.0.1 - - [24/Jun/2025 14:54:10] "[35m[1mPOST /api/v1/images HTTP/1.1[0m" 201 -
2025-06-24 14:54:57,451 ERROR __main__ Database error: (pymysql.err.DataError) (1406, "Data too long for column 'image' at row 1")
[SQL: INSERT INTO singora_images (image, label_name, date, timestamp) VALUES (%(image)s, %(label_name)s, %(date)s, %(timestamp)s)]
[parameters: {'image': b'\xff\xd8\xff\xe0\x00\x10JFIF\x00\x01\x01\x01\x00`\x00`\x00\x00\xff\xe10\xcaExif\x00\x00MM\x00*\x00\x00\x00\x08\x00\x04\x011\x00\x02\x00\x00\x00\x0b\ ... (330930 characters truncated) ... 7\x1f\xc2EF\xf0\x95\xe4\x8f\xccV\xfb[\x9488\xfa\xd3\r\xa89\xe3\xad1\x1c\xfb\xc6\t\xe9\x83\xf4\xa6\x14\x07\xb0&\xb7\xda\xd9Oa\xc5@\xd6H{u\xa63\xff\xd9', 'label_name': 'Naps, slubs,Naps', 'date': datetime.date(2025, 6, 24), 'timestamp': datetime.datetime(2025, 6, 24, 9, 24, 57, 443938)}]
(Background on this error at: https://sqlalche.me/e/20/9h9h)
2025-06-24 14:54:57,452 INFO werkzeug 127.0.0.1 - - [24/Jun/2025 14:54:57] "[35m[1mPOST /api/v1/images HTTP/1.1[0m" 500 -
2025-06-24 14:56:26,623 ERROR __main__ Database error: (pymysql.err.DataError) (1406, "Data too long for column 'image' at row 1")
[SQL: INSERT INTO singora_images (image, label_name, date, timestamp) VALUES (%(image)s, %(label_name)s, %(date)s, %(timestamp)s)]
[parameters: {'image': b'\xff\xd8\xff\xe0\x00\x10JFIF\x00\x01\x01\x01\x00`\x00`\x00\x00\xff\xe10\xcaExif\x00\x00MM\x00*\x00\x00\x00\x08\x00\x04\x011\x00\x02\x00\x00\x00\x0b\ ... (330930 characters truncated) ... 7\x1f\xc2EF\xf0\x95\xe4\x8f\xccV\xfb[\x9488\xfa\xd3\r\xa89\xe3\xad1\x1c\xfb\xc6\t\xe9\x83\xf4\xa6\x14\x07\xb0&\xb7\xda\xd9Oa\xc5@\xd6H{u\xa63\xff\xd9', 'label_name': 'Naps, slubs,Naps', 'date': datetime.date(2025, 6, 24), 'timestamp': datetime.datetime(2025, 6, 24, 9, 26, 26, 615757)}]
(Background on this error at: https://sqlalche.me/e/20/9h9h)
2025-06-24 14:56:26,624 INFO werkzeug 127.0.0.1 - - [24/Jun/2025 14:56:26] "[35m[1mPOST /api/v1/images HTTP/1.1[0m" 500 -
2025-06-24 15:04:15,808 INFO __main__ Database tables created successfully
2025-06-24 15:04:15,824 INFO werkzeug [31m[1mWARNING: This is a development server. Do not use it in a production deployment. Use a production WSGI server instead.[0m
 * Running on all addresses (0.0.0.0)
 * Running on http://127.0.0.1:5000
 * Running on http://192.168.1.160:5000
2025-06-24 15:04:15,824 INFO werkzeug [33mPress CTRL+C to quit[0m
2025-06-24 15:05:08,652 ERROR __main__ Database error: (pymysql.err.DataError) (1406, "Data too long for column 'image' at row 1")
[SQL: INSERT INTO singora_images (image, label_name, date, timestamp) VALUES (%(image)s, %(label_name)s, %(date)s, %(timestamp)s)]
[parameters: {'image': b'\xff\xd8\xff\xe0\x00\x10JFIF\x00\x01\x01\x01\x00`\x00`\x00\x00\xff\xe10\xcaExif\x00\x00MM\x00*\x00\x00\x00\x08\x00\x04\x011\x00\x02\x00\x00\x00\x0b\ ... (330930 characters truncated) ... 7\x1f\xc2EF\xf0\x95\xe4\x8f\xccV\xfb[\x9488\xfa\xd3\r\xa89\xe3\xad1\x1c\xfb\xc6\t\xe9\x83\xf4\xa6\x14\x07\xb0&\xb7\xda\xd9Oa\xc5@\xd6H{u\xa63\xff\xd9', 'label_name': 'Naps, slubs,Naps', 'date': datetime.date(2025, 6, 24), 'timestamp': datetime.datetime(2025, 6, 24, 9, 35, 8, 643578)}]
(Background on this error at: https://sqlalche.me/e/20/9h9h)
2025-06-24 15:05:08,652 ERROR app Exception on /api/v1/images [POST]
Traceback (most recent call last):
  File "D:\singora_app\.myenv\lib\site-packages\sqlalchemy\engine\base.py", line 1963, in _exec_single_context
    self.dialect.do_execute(
  File "D:\singora_app\.myenv\lib\site-packages\sqlalchemy\engine\default.py", line 943, in do_execute
    cursor.execute(statement, parameters)
  File "D:\singora_app\.myenv\lib\site-packages\pymysql\cursors.py", line 153, in execute
    result = self._query(query)
  File "D:\singora_app\.myenv\lib\site-packages\pymysql\cursors.py", line 322, in _query
    conn.query(q)
  File "D:\singora_app\.myenv\lib\site-packages\pymysql\connections.py", line 558, in query
    self._affected_rows = self._read_query_result(unbuffered=unbuffered)
  File "D:\singora_app\.myenv\lib\site-packages\pymysql\connections.py", line 822, in _read_query_result
    result.read()
  File "D:\singora_app\.myenv\lib\site-packages\pymysql\connections.py", line 1200, in read
    first_packet = self.connection._read_packet()
  File "D:\singora_app\.myenv\lib\site-packages\pymysql\connections.py", line 772, in _read_packet
    packet.raise_for_error()
  File "D:\singora_app\.myenv\lib\site-packages\pymysql\protocol.py", line 221, in raise_for_error
    err.raise_mysql_exception(self._data)
  File "D:\singora_app\.myenv\lib\site-packages\pymysql\err.py", line 143, in raise_mysql_exception
    raise errorclass(errno, errval)
pymysql.err.DataError: (1406, "Data too long for column 'image' at row 1")

The above exception was the direct cause of the following exception:

Traceback (most recent call last):
  File "D:\singora_app\app.py", line 199, in upload_image
    db.session.commit()
  File "D:\singora_app\.myenv\lib\site-packages\sqlalchemy\orm\scoping.py", line 599, in commit
    return self._proxied.commit()
  File "D:\singora_app\.myenv\lib\site-packages\sqlalchemy\orm\session.py", line 2032, in commit
    trans.commit(_to_root=True)
  File "<string>", line 2, in commit
  File "D:\singora_app\.myenv\lib\site-packages\sqlalchemy\orm\state_changes.py", line 139, in _go
    ret_value = fn(self, *arg, **kw)
  File "D:\singora_app\.myenv\lib\site-packages\sqlalchemy\orm\session.py", line 1313, in commit
    self._prepare_impl()
  File "<string>", line 2, in _prepare_impl
  File "D:\singora_app\.myenv\lib\site-packages\sqlalchemy\orm\state_changes.py", line 139, in _go
    ret_value = fn(self, *arg, **kw)
  File "D:\singora_app\.myenv\lib\site-packages\sqlalchemy\orm\session.py", line 1288, in _prepare_impl
    self.session.flush()
  File "D:\singora_app\.myenv\lib\site-packages\sqlalchemy\orm\session.py", line 4345, in flush
    self._flush(objects)
  File "D:\singora_app\.myenv\lib\site-packages\sqlalchemy\orm\session.py", line 4480, in _flush
    with util.safe_reraise():
  File "D:\singora_app\.myenv\lib\site-packages\sqlalchemy\util\langhelpers.py", line 224, in __exit__
    raise exc_value.with_traceback(exc_tb)
  File "D:\singora_app\.myenv\lib\site-packages\sqlalchemy\orm\session.py", line 4441, in _flush
    flush_context.execute()
  File "D:\singora_app\.myenv\lib\site-packages\sqlalchemy\orm\unitofwork.py", line 466, in execute
    rec.execute(self)
  File "D:\singora_app\.myenv\lib\site-packages\sqlalchemy\orm\unitofwork.py", line 642, in execute
    util.preloaded.orm_persistence.save_obj(
  File "D:\singora_app\.myenv\lib\site-packages\sqlalchemy\orm\persistence.py", line 93, in save_obj
    _emit_insert_statements(
  File "D:\singora_app\.myenv\lib\site-packages\sqlalchemy\orm\persistence.py", line 1233, in _emit_insert_statements
    result = connection.execute(
  File "D:\singora_app\.myenv\lib\site-packages\sqlalchemy\engine\base.py", line 1415, in execute
    return meth(
  File "D:\singora_app\.myenv\lib\site-packages\sqlalchemy\sql\elements.py", line 523, in _execute_on_connection
    return connection._execute_clauseelement(
  File "D:\singora_app\.myenv\lib\site-packages\sqlalchemy\engine\base.py", line 1637, in _execute_clauseelement
    ret = self._execute_context(
  File "D:\singora_app\.myenv\lib\site-packages\sqlalchemy\engine\base.py", line 1842, in _execute_context
    return self._exec_single_context(
  File "D:\singora_app\.myenv\lib\site-packages\sqlalchemy\engine\base.py", line 1982, in _exec_single_context
    self._handle_dbapi_exception(
  File "D:\singora_app\.myenv\lib\site-packages\sqlalchemy\engine\base.py", line 2351, in _handle_dbapi_exception
    raise sqlalchemy_exception.with_traceback(exc_info[2]) from e
  File "D:\singora_app\.myenv\lib\site-packages\sqlalchemy\engine\base.py", line 1963, in _exec_single_context
    self.dialect.do_execute(
  File "D:\singora_app\.myenv\lib\site-packages\sqlalchemy\engine\default.py", line 943, in do_execute
    cursor.execute(statement, parameters)
  File "D:\singora_app\.myenv\lib\site-packages\pymysql\cursors.py", line 153, in execute
    result = self._query(query)
  File "D:\singora_app\.myenv\lib\site-packages\pymysql\cursors.py", line 322, in _query
    conn.query(q)
  File "D:\singora_app\.myenv\lib\site-packages\pymysql\connections.py", line 558, in query
    self._affected_rows = self._read_query_result(unbuffered=unbuffered)
  File "D:\singora_app\.myenv\lib\site-packages\pymysql\connections.py", line 822, in _read_query_result
    result.read()
  File "D:\singora_app\.myenv\lib\site-packages\pymysql\connections.py", line 1200, in read
    first_packet = self.connection._read_packet()
  File "D:\singora_app\.myenv\lib\site-packages\pymysql\connections.py", line 772, in _read_packet
    packet.raise_for_error()
  File "D:\singora_app\.myenv\lib\site-packages\pymysql\protocol.py", line 221, in raise_for_error
    err.raise_mysql_exception(self._data)
  File "D:\singora_app\.myenv\lib\site-packages\pymysql\err.py", line 143, in raise_mysql_exception
    raise errorclass(errno, errval)
sqlalchemy.exc.DataError: (pymysql.err.DataError) (1406, "Data too long for column 'image' at row 1")
[SQL: INSERT INTO singora_images (image, label_name, date, timestamp) VALUES (%(image)s, %(label_name)s, %(date)s, %(timestamp)s)]
[parameters: {'image': b'\xff\xd8\xff\xe0\x00\x10JFIF\x00\x01\x01\x01\x00`\x00`\x00\x00\xff\xe10\xcaExif\x00\x00MM\x00*\x00\x00\x00\x08\x00\x04\x011\x00\x02\x00\x00\x00\x0b\ ... (330930 characters truncated) ... 7\x1f\xc2EF\xf0\x95\xe4\x8f\xccV\xfb[\x9488\xfa\xd3\r\xa89\xe3\xad1\x1c\xfb\xc6\t\xe9\x83\xf4\xa6\x14\x07\xb0&\xb7\xda\xd9Oa\xc5@\xd6H{u\xa63\xff\xd9', 'label_name': 'Naps, slubs,Naps', 'date': datetime.date(2025, 6, 24), 'timestamp': datetime.datetime(2025, 6, 24, 9, 35, 8, 643578)}]
(Background on this error at: https://sqlalche.me/e/20/9h9h)

During handling of the above exception, another exception occurred:

Traceback (most recent call last):
  File "D:\singora_app\.myenv\lib\site-packages\flask\app.py", line 2190, in wsgi_app
    response = self.full_dispatch_request()
  File "D:\singora_app\.myenv\lib\site-packages\flask\app.py", line 1486, in full_dispatch_request
    rv = self.handle_user_exception(e)
  File "D:\singora_app\.myenv\lib\site-packages\flask_cors\extension.py", line 176, in wrapped_function
    return cors_after_request(app.make_response(f(*args, **kwargs)))
  File "D:\singora_app\.myenv\lib\site-packages\flask\app.py", line 1484, in full_dispatch_request
    rv = self.dispatch_request()
  File "D:\singora_app\.myenv\lib\site-packages\flask\app.py", line 1469, in dispatch_request
    return self.ensure_sync(self.view_functions[rule.endpoint])(**view_args)
  File "D:\singora_app\app.py", line 104, in decorated_function
    return f(*args, **kwargs)
  File "D:\singora_app\app.py", line 211, in upload_image
    body = getattr(e.response, "body", str(e))
AttributeError: 'DataError' object has no attribute 'response'
2025-06-24 15:05:08,751 ERROR __main__ Internal server error: 500 Internal Server Error: The server encountered an internal error and was unable to complete your request. Either the server is overloaded or there is an error in the application.
2025-06-24 15:05:08,751 INFO werkzeug 127.0.0.1 - - [24/Jun/2025 15:05:08] "[35m[1mPOST /api/v1/images HTTP/1.1[0m" 500 -
2025-06-24 15:07:42,498 INFO __main__ Database tables created successfully
2025-06-24 15:07:42,510 INFO werkzeug [31m[1mWARNING: This is a development server. Do not use it in a production deployment. Use a production WSGI server instead.[0m
 * Running on all addresses (0.0.0.0)
 * Running on http://127.0.0.1:5000
 * Running on http://192.168.1.160:5000
2025-06-24 15:07:42,510 INFO werkzeug [33mPress CTRL+C to quit[0m
2025-06-24 15:07:49,015 ERROR __main__ Database error: (pymysql.err.DataError) (1406, "Data too long for column 'image' at row 1")
[SQL: INSERT INTO singora_images (image, label_name, date, timestamp) VALUES (%(image)s, %(label_name)s, %(date)s, %(timestamp)s)]
[parameters: {'image': b'\xff\xd8\xff\xe0\x00\x10JFIF\x00\x01\x01\x01\x00`\x00`\x00\x00\xff\xe10\xcaExif\x00\x00MM\x00*\x00\x00\x00\x08\x00\x04\x011\x00\x02\x00\x00\x00\x0b\ ... (330930 characters truncated) ... 7\x1f\xc2EF\xf0\x95\xe4\x8f\xccV\xfb[\x9488\xfa\xd3\r\xa89\xe3\xad1\x1c\xfb\xc6\t\xe9\x83\xf4\xa6\x14\x07\xb0&\xb7\xda\xd9Oa\xc5@\xd6H{u\xa63\xff\xd9', 'label_name': 'Naps, slubs,Naps', 'date': datetime.date(2025, 6, 24), 'timestamp': datetime.datetime(2025, 6, 24, 9, 37, 49, 7654)}]
(Background on this error at: https://sqlalche.me/e/20/9h9h)
2025-06-24 15:07:49,017 INFO werkzeug 127.0.0.1 - - [24/Jun/2025 15:07:49] "[35m[1mPOST /api/v1/images HTTP/1.1[0m" 500 -
2025-06-24 15:13:41,145 INFO __main__ Image uploaded successfully with ID: 3
2025-06-24 15:13:41,147 INFO werkzeug 127.0.0.1 - - [24/Jun/2025 15:13:41] "[35m[1mPOST /api/v1/images HTTP/1.1[0m" 201 -
2025-06-24 15:14:02,109 INFO __main__ Image uploaded successfully with ID: 4
2025-06-24 15:14:02,111 INFO werkzeug 127.0.0.1 - - [24/Jun/2025 15:14:02] "[35m[1mPOST /api/v1/images HTTP/1.1[0m" 201 -
2025-06-24 15:14:50,251 INFO werkzeug 127.0.0.1 - - [24/Jun/2025 15:14:50] "[31m[1mPOST /api/v1/images HTTP/1.1[0m" 400 -
2025-06-24 15:15:13,287 INFO werkzeug 127.0.0.1 - - [24/Jun/2025 15:15:13] "[31m[1mPOST /api/v1/images HTTP/1.1[0m" 400 -
2025-06-24 15:15:42,164 INFO __main__ Image uploaded successfully with ID: 5
2025-06-24 15:15:42,166 INFO werkzeug 127.0.0.1 - - [24/Jun/2025 15:15:42] "[35m[1mPOST /api/v1/images HTTP/1.1[0m" 201 -
2025-06-24 15:17:09,930 INFO werkzeug 127.0.0.1 - - [24/Jun/2025 15:17:09] "[31m[1mGET /api/v1/images HTTP/1.1[0m" 401 -
2025-06-24 15:17:10,197 INFO werkzeug 127.0.0.1 - - [24/Jun/2025 15:17:10] "[33mGET /favicon.ico HTTP/1.1[0m" 404 -
2025-06-24 15:17:46,203 INFO werkzeug 127.0.0.1 - - [24/Jun/2025 15:17:46] "[31m[1mGET /api/v1/images HTTP/1.1[0m" 401 -
2025-06-24 15:18:08,890 INFO werkzeug 127.0.0.1 - - [24/Jun/2025 15:18:08] "GET /api/v1/images HTTP/1.1" 200 -
2025-06-24 15:19:32,164 INFO werkzeug 127.0.0.1 - - [24/Jun/2025 15:19:32] "GET /api/v1/images?label_name=Naps HTTP/1.1" 200 -
2025-06-24 15:19:48,228 INFO werkzeug 127.0.0.1 - - [24/Jun/2025 15:19:48] "GET /api/v1/images?label_name=Naps HTTP/1.1" 200 -
2025-06-24 15:20:56,458 INFO werkzeug 127.0.0.1 - - [24/Jun/2025 15:20:56] "GET /api/v1/images?label_name=Naps&date=2025-06-24 HTTP/1.1" 200 -
2025-06-24 15:21:14,220 INFO werkzeug 127.0.0.1 - - [24/Jun/2025 15:21:14] "GET /api/v1/images?label_name=Naps&date=2025-06-23 HTTP/1.1" 200 -
2025-06-24 15:21:29,432 INFO werkzeug 127.0.0.1 - - [24/Jun/2025 15:21:29] "GET /api/v1/images?label_name=Naps&date=2025-06-24 HTTP/1.1" 200 -
2025-06-24 16:10:31,993 INFO __main__ Database tables created successfully
2025-06-24 16:10:32,008 INFO werkzeug [31m[1mWARNING: This is a development server. Do not use it in a production deployment. Use a production WSGI server instead.[0m
 * Running on all addresses (0.0.0.0)
 * Running on http://127.0.0.1:5000
 * Running on http://192.168.1.160:5000
2025-06-24 16:10:32,008 INFO werkzeug [33mPress CTRL+C to quit[0m
2025-06-24 16:12:03,064 ERROR __main__ Download images by label error: 'ImageData' object has no attribute 'image_data'
2025-06-24 16:12:03,066 INFO werkzeug 127.0.0.1 - - [24/Jun/2025 16:12:03] "[35m[1mGET /api/v1/images/download/label/Naps HTTP/1.1[0m" 500 -
2025-06-24 16:22:48,939 INFO __main__ Database tables created successfully
2025-06-24 16:22:48,952 INFO werkzeug [31m[1mWARNING: This is a development server. Do not use it in a production deployment. Use a production WSGI server instead.[0m
 * Running on all addresses (0.0.0.0)
 * Running on http://127.0.0.1:5000
 * Running on http://192.168.1.160:5000
2025-06-24 16:22:48,952 INFO werkzeug [33mPress CTRL+C to quit[0m
2025-06-24 16:22:59,419 INFO werkzeug 127.0.0.1 - - [24/Jun/2025 16:22:59] "GET /api/v1/images/download/label/Naps HTTP/1.1" 200 -
2025-06-24 16:32:23,813 INFO werkzeug 127.0.0.1 - - [24/Jun/2025 16:32:23] "GET /api/v1/images/download/label/Naps/date/2025-06-24?format=json&page=1&per_page=50 HTTP/1.1" 200 -
2025-06-24 16:34:18,877 INFO werkzeug 127.0.0.1 - - [24/Jun/2025 16:34:18] "[31m[1mGET /api/v1/images/download/label/Naps/date/2025-06-24?format=zip HTTP/1.1[0m" 401 -
2025-06-24 16:34:51,184 INFO werkzeug 127.0.0.1 - - [24/Jun/2025 16:34:51] "GET /api/v1/images/download/label/Naps/date/2025-06-24?format=zip HTTP/1.1" 200 -
2025-06-24 17:16:32,244 INFO __main__ Database tables created successfully
2025-06-24 17:16:32,256 INFO werkzeug [31m[1mWARNING: This is a development server. Do not use it in a production deployment. Use a production WSGI server instead.[0m
 * Running on all addresses (0.0.0.0)
 * Running on http://127.0.0.1:5000
 * Running on http://192.168.1.160:5000
2025-06-24 17:16:32,256 INFO werkzeug [33mPress CTRL+C to quit[0m
2025-06-24 17:19:19,560 INFO werkzeug 127.0.0.1 - - [24/Jun/2025 17:19:19] "GET /api/v1/images/download/label/Naps HTTP/1.1" 200 -
2025-06-24 17:19:23,928 INFO werkzeug 127.0.0.1 - - [24/Jun/2025 17:19:23] "GET /api/v1/images/download/label/Naps HTTP/1.1" 200 -
2025-06-24 17:21:19,088 INFO werkzeug 127.0.0.1 - - [24/Jun/2025 17:21:19] "[31m[1mGET /api/v1/images/download/label/Naps HTTP/1.1[0m" 401 -
2025-06-24 17:25:09,276 INFO werkzeug 127.0.0.1 - - [24/Jun/2025 17:25:09] "[31m[1mGET /api/v1/images/download/date/2025-06-24 HTTP/1.1[0m" 401 -
2025-06-24 17:25:27,623 INFO werkzeug 127.0.0.1 - - [24/Jun/2025 17:25:27] "[31m[1mGET /api/v1/images/download/date/2025-06-24 HTTP/1.1[0m" 401 -
2025-06-24 17:27:02,081 INFO werkzeug 127.0.0.1 - - [24/Jun/2025 17:27:02] "[31m[1mGET /api/v1/images/download/label/Naps?format=json HTTP/1.1[0m" 401 -
2025-06-24 17:30:10,555 INFO werkzeug 127.0.0.1 - - [24/Jun/2025 17:30:10] "[31m[1mGET /api/v1/images/download/label/Naps?format=json HTTP/1.1[0m" 401 -
2025-06-24 17:30:43,116 INFO werkzeug 127.0.0.1 - - [24/Jun/2025 17:30:43] "GET /api/v1/images/download/label/Naps?format=json HTTP/1.1" 200 -
2025-06-24 17:31:30,501 INFO werkzeug 127.0.0.1 - - [24/Jun/2025 17:31:30] "[31m[1mGET /api/v1/images/download/date/2025-06-24 HTTP/1.1[0m" 401 -
2025-06-24 17:31:52,004 INFO werkzeug 127.0.0.1 - - [24/Jun/2025 17:31:52] "[31m[1mGET /api/v1/images/download/date/2025-06-24 HTTP/1.1[0m" 401 -
2025-06-25 10:44:07,315 INFO __main__ Database tables created successfully
2025-06-25 10:44:07,330 INFO werkzeug [31m[1mWARNING: This is a development server. Do not use it in a production deployment. Use a production WSGI server instead.[0m
 * Running on all addresses (0.0.0.0)
 * Running on http://127.0.0.1:5000
 * Running on http://172.17.39.80:5000
2025-06-25 10:44:07,330 INFO werkzeug [33mPress CTRL+C to quit[0m
2025-06-25 10:44:27,006 INFO werkzeug 127.0.0.1 - - [25/Jun/2025 10:44:27] "GET /api/v1/images/download/date/2025-06-24 HTTP/1.1" 200 -
2025-06-25 10:53:26,780 INFO werkzeug 127.0.0.1 - - [25/Jun/2025 10:53:26] "GET /api/v1/images/download/label/Naps HTTP/1.1" 200 -
2025-06-25 10:59:59,476 INFO werkzeug 127.0.0.1 - - [25/Jun/2025 10:59:59] "GET /api/v1/images/download/all HTTP/1.1" 200 -
2025-06-25 11:02:36,714 INFO werkzeug 127.0.0.1 - - [25/Jun/2025 11:02:36] "GET /api/v1/images/download/info HTTP/1.1" 200 -
